{
  "DataVersion": 3955,
  "size": [
    13,
    8,
    13
  ],
  "palette": [
    {
      "Name": "minecraft:mossy_stone_bricks"
    },
    {
      "Name": "minecraft:stone_bricks"
    },
    {
      "Name": "minecraft:oak_planks"
    },
    {
      "Name": "minecraft:grass_block",
      "Properties": {
        "snowy": "false"
      }
    },
    {
      "Name": "minecraft:smooth_stone"
    },
    {
      "Name": "minecraft:spruce_log",
      "Properties": {
        "axis": "y"
      }
    },
    {
      "Name": "minecraft:stone_brick_slab",
      "Properties": {
        "type": "bottom",
        "waterlogged": "false"
      }
    },
    {
      "Name": "minecraft:poppy"
    },
    {
      "Name": "minecraft:white_bed",
      "Properties": {
        "facing": "north",
        "occupied": "false",
        "part": "head"
      }
    },
    {
      "Name": "minecraft:white_bed",
      "Properties": {
        "facing": "north",
        "occupied": "false",
        "part": "foot"
      }
    },
    {
      "Name": "minecraft:oxeye_daisy"
    },
    {
      "Name": "minecraft:spruce_fence",
      "Properties": {
        "east": "false",
        "north": "false",
        "south": "false",
        "waterlogged": "false",
        "west": "false"
      }
    },
    {
      "Name": "minecraft:spruce_door",
      "Properties": {
        "facing": "south",
        "half": "lower",
        "hinge": "left",
        "open": "false",
        "powered": "false"
      }
    },
    {
      "Name": "minecraft:glass"
    },
    {
      "Name": "minecraft:spruce_door",
      "Properties": {
        "facing": "south",
        "half": "upper",
        "hinge": "left",
        "open": "false",
        "powered": "false"
      }
    },
    {
      "Name": "minecraft:lantern",
      "Properties": {
        "hanging": "false",
        "waterlogged": "false"
      }
    },
    {
      "Name": "minecraft:spruce_log",
      "Properties": {
        "axis": "z"
      }
    },
    {
      "Name": "minecraft:spruce_log",
      "Properties": {
        "axis": "x"
      }
    },
    {
      "Name": "minecraft:lantern",
      "Properties": {
        "hanging": "true",
        "waterlogged": "false"
      }
    },
    {
      "Name": "minecraft:spruce_slab",
      "Properties": {
        "type": "bottom",
        "waterlogged": "false"
      }
    },
    {
      "Name": "minecraft:spruce_slab",
      "Properties": {
        "type": "top",
        "waterlogged": "false"
      }
    },
    {
      "Name": "minecraft:spruce_slab",
      "Properties": {
        "type": "double",
        "waterlogged": "false"
      }
    }
  ],
  "blocks": [
    {
      "pos": [
        0,
        0,
        0
      ],
      "state": 0
    },
    {
      "pos": [
        0,
        0,
        1
      ],
      "state": 1
    },
    {
      "pos": [
        0,
        0,
        2
      ],
      "state": 1
    },
    {
      "pos": [
        0,
        0,
        3
      ],
      "state": 1
    },
    {
      "pos": [
        0,
        0,
        4
      ],
      "state": 1
    },
    {
      "pos": [
        0,
        0,
        5
      ],
      "state": 1
    },
    {
      "pos": [
        0,
        0,
        6
      ],
      "state": 1
    },
    {
      "pos": [
        0,
        0,
        7
      ],
      "state": 1
    },
    {
      "pos": [
        0,
        0,
        8
      ],
      "state": 1
    },
    {
      "pos": [
        0,
        0,
        9
      ],
      "state": 1
    },
    {
      "pos": [
        0,
        0,
        10
      ],
      "state": 1
    },
    {
      "pos": [
        0,
        0,
        11
      ],
      "state": 0
    },
    {
      "pos": [
        0,
        0,
        12
      ],
      "state": 1
    },
    {
      "pos": [
        1,
        0,
        0
      ],
      "state": 1
    },
    {
      "pos": [
        1,
        0,
        1
      ],
      "state": 1
    },
    {
      "pos": [
        1,
        0,
        2
      ],
      "state": 1
    },
    {
      "pos": [
        1,
        0,
        3
      ],
      "state": 1
    },
    {
      "pos": [
        1,
        0,
        4
      ],
      "state": 1
    },
    {
      "pos": [
        1,
        0,
        5
      ],
      "state": 1
    },
    {
      "pos": [
        1,
        0,
        6
      ],
      "state": 0
    },
    {
      "pos": [
        1,
        0,
        7
      ],
      "state": 1
    },
    {
      "pos": [
        1,
        0,
        8
      ],
      "state": 1
    },
    {
      "pos": [
        1,
        0,
        9
      ],
      "state": 1
    },
    {
      "pos": [
        1,
        0,
        10
      ],
      "state": 1
    },
    {
      "pos": [
        1,
        0,
        11
      ],
      "state": 1
    },
    {
      "pos": [
        1,
        0,
        12
      ],
      "state": 1
    },
    {
      "pos": [
        2,
        0,
        0
      ],
      "state": 1
    },
    {
      "pos": [
        2,
        0,
        1
      ],
      "state": 2
    },
    {
      "pos": [
        2,
        0,
        2
      ],
      "state": 2
    },
    {
      "pos": [
        2,
        0,
        3
      ],
      "state": 2
    },
    {
      "pos": [
        2,
        0,
        4
      ],
      "state": 2
    },
    {
      "pos": [
        2,
        0,
        5
      ],
      "state": 2
    },
    {
      "pos": [
        2,
        0,
        6
      ],
      "state": 2
    },
    {
      "pos": [
        2,
        0,
        7
      ],
      "state": 2
    },
    {
      "pos": [
        2,
        0,
        8
      ],
      "state": 2
    },
    {
      "pos": [
        2,
        0,
        9
      ],
      "state": 2
    },
    {
      "pos": [
        2,
        0,
        10
      ],
      "state": 1
    },
    {
      "pos": [
        2,
        0,
        11
      ],
      "state": 1
    },
    {
      "pos": [
        2,
        0,
        12
      ],
      "state": 3
    },
    {
      "pos": [
        3,
        0,
        0
      ],
      "state": 1
    },
    {
      "pos": [
        3,
        0,
        1
      ],
      "state": 2
    },
    {
      "pos": [
        3,
        0,
        2
      ],
      "state": 2
    },
    {
      "pos": [
        3,
        0,
        3
      ],
      "state": 2
    },
    {
      "pos": [
        3,
        0,
        4
      ],
      "state": 2
    },
    {
      "pos": [
        3,
        0,
        5
      ],
      "state": 2
    },
    {
      "pos": [
        3,
        0,
        6
      ],
      "state": 2
    },
    {
      "pos": [
        3,
        0,
        7
      ],
      "state": 2
    },
    {
      "pos": [
        3,
        0,
        8
      ],
      "state": 2
    },
    {
      "pos": [
        3,
        0,
        9
      ],
      "state": 2
    },
    {
      "pos": [
        3,
        0,
        10
      ],
      "state": 1
    },
    {
      "pos": [
        3,
        0,
        11
      ],
      "state": 1
    },
    {
      "pos": [
        3,
        0,
        12
      ],
      "state": 3
    },
    {
      "pos": [
        4,
        0,
        0
      ],
      "state": 1
    },
    {
      "pos": [
        4,
        0,
        1
      ],
      "state": 2
    },
    {
      "pos": [
        4,
        0,
        2
      ],
      "state": 2
    },
    {
      "pos": [
        4,
        0,
        3
      ],
      "state": 2
    },
    {
      "pos": [
        4,
        0,
        4
      ],
      "state": 2
    },
    {
      "pos": [
        4,
        0,
        5
      ],
      "state": 2
    },
    {
      "pos": [
        4,
        0,
        6
      ],
      "state": 2
    },
    {
      "pos": [
        4,
        0,
        7
      ],
      "state": 2
    },
    {
      "pos": [
        4,
        0,
        8
      ],
      "state": 2
    },
    {
      "pos": [
        4,
        0,
        9
      ],
      "state": 2
    },
    {
      "pos": [
        4,
        0,
        10
      ],
      "state": 1
    },
    {
      "pos": [
        4,
        0,
        11
      ],
      "state": 1
    },
    {
      "pos": [
        4,
        0,
        12
      ],
      "state": 1
    },
    {
      "pos": [
        5,
        0,
        0
      ],
      "state": 4
    },
    {
      "pos": [
        5,
        0,
        1
      ],
      "state": 2
    },
    {
      "pos": [
        5,
        0,
        2
      ],
      "state": 2
    },
    {
      "pos": [
        5,
        0,
        3
      ],
      "state": 2
    },
    {
      "pos": [
        5,
        0,
        4
      ],
      "state": 2
    },
    {
      "pos": [
        5,
        0,
        5
      ],
      "state": 2
    },
    {
      "pos": [
        5,
        0,
        6
      ],
      "state": 2
    },
    {
      "pos": [
        5,
        0,
        7
      ],
      "state": 2
    },
    {
      "pos": [
        5,
        0,
        8
      ],
      "state": 2
    },
    {
      "pos": [
        5,
        0,
        9
      ],
      "state": 2
    },
    {
      "pos": [
        5,
        0,
        10
      ],
      "state": 4
    },
    {
      "pos": [
        5,
        0,
        11
      ],
      "state": 4
    },
    {
      "pos": [
        5,
        0,
        12
      ],
      "state": 4
    },
    {
      "pos": [
        6,
        0,
        0
      ],
      "state": 1
    },
    {
      "pos": [
        6,
        0,
        1
      ],
      "state": 2
    },
    {
      "pos": [
        6,
        0,
        2
      ],
      "state": 2
    },
    {
      "pos": [
        6,
        0,
        3
      ],
      "state": 2
    },
    {
      "pos": [
        6,
        0,
        4
      ],
      "state": 2
    },
    {
      "pos": [
        6,
        0,
        5
      ],
      "state": 2
    },
    {
      "pos": [
        6,
        0,
        6
      ],
      "state": 2
    },
    {
      "pos": [
        6,
        0,
        7
      ],
      "state": 2
    },
    {
      "pos": [
        6,
        0,
        8
      ],
      "state": 2
    },
    {
      "pos": [
        6,
        0,
        9
      ],
      "state": 2
    },
    {
      "pos": [
        6,
        0,
        10
      ],
      "state": 1
    },
    {
      "pos": [
        6,
        0,
        11
      ],
      "state": 1
    },
    {
      "pos": [
        6,
        0,
        12
      ],
      "state": 1
    },
    {
      "pos": [
        7,
        0,
        0
      ],
      "state": 4
    },
    {
      "pos": [
        7,
        0,
        1
      ],
      "state": 2
    },
    {
      "pos": [
        7,
        0,
        2
      ],
      "state": 2
    },
    {
      "pos": [
        7,
        0,
        3
      ],
      "state": 2
    },
    {
      "pos": [
        7,
        0,
        4
      ],
      "state": 2
    },
    {
      "pos": [
        7,
        0,
        5
      ],
      "state": 2
    },
    {
      "pos": [
        7,
        0,
        6
      ],
      "state": 2
    },
    {
      "pos": [
        7,
        0,
        7
      ],
      "state": 2
    },
    {
      "pos": [
        7,
        0,
        8
      ],
      "state": 2
    },
    {
      "pos": [
        7,
        0,
        9
      ],
      "state": 2
    },
    {
      "pos": [
        7,
        0,
        10
      ],
      "state": 4
    },
    {
      "pos": [
        7,
        0,
        11
      ],
      "state": 4
    },
    {
      "pos": [
        7,
        0,
        12
      ],
      "state": 4
    },
    {
      "pos": [
        8,
        0,
        0
      ],
      "state": 1
    },
    {
      "pos": [
        8,
        0,
        1
      ],
      "state": 2
    },
    {
      "pos": [
        8,
        0,
        2
      ],
      "state": 2
    },
    {
      "pos": [
        8,
        0,
        3
      ],
      "state": 2
    },
    {
      "pos": [
        8,
        0,
        4
      ],
      "state": 2
    },
    {
      "pos": [
        8,
        0,
        5
      ],
      "state": 2
    },
    {
      "pos": [
        8,
        0,
        6
      ],
      "state": 2
    },
    {
      "pos": [
        8,
        0,
        7
      ],
      "state": 2
    },
    {
      "pos": [
        8,
        0,
        8
      ],
      "state": 2
    },
    {
      "pos": [
        8,
        0,
        9
      ],
      "state": 2
    },
    {
      "pos": [
        8,
        0,
        10
      ],
      "state": 1
    },
    {
      "pos": [
        8,
        0,
        11
      ],
      "state": 1
    },
    {
      "pos": [
        8,
        0,
        12
      ],
      "state": 1
    },
    {
      "pos": [
        9,
        0,
        0
      ],
      "state": 1
    },
    {
      "pos": [
        9,
        0,
        1
      ],
      "state": 2
    },
    {
      "pos": [
        9,
        0,
        2
      ],
      "state": 2
    },
    {
      "pos": [
        9,
        0,
        3
      ],
      "state": 2
    },
    {
      "pos": [
        9,
        0,
        4
      ],
      "state": 2
    },
    {
      "pos": [
        9,
        0,
        5
      ],
      "state": 2
    },
    {
      "pos": [
        9,
        0,
        6
      ],
      "state": 2
    },
    {
      "pos": [
        9,
        0,
        7
      ],
      "state": 2
    },
    {
      "pos": [
        9,
        0,
        8
      ],
      "state": 2
    },
    {
      "pos": [
        9,
        0,
        9
      ],
      "state": 2
    },
    {
      "pos": [
        9,
        0,
        10
      ],
      "state": 0
    },
    {
      "pos": [
        9,
        0,
        11
      ],
      "state": 1
    },
    {
      "pos": [
        9,
        0,
        12
      ],
      "state": 3
    },
    {
      "pos": [
        10,
        0,
        0
      ],
      "state": 1
    },
    {
      "pos": [
        10,
        0,
        1
      ],
      "state": 2
    },
    {
      "pos": [
        10,
        0,
        2
      ],
      "state": 2
    },
    {
      "pos": [
        10,
        0,
        3
      ],
      "state": 2
    },
    {
      "pos": [
        10,
        0,
        4
      ],
      "state": 2
    },
    {
      "pos": [
        10,
        0,
        5
      ],
      "state": 2
    },
    {
      "pos": [
        10,
        0,
        6
      ],
      "state": 2
    },
    {
      "pos": [
        10,
        0,
        7
      ],
      "state": 2
    },
    {
      "pos": [
        10,
        0,
        8
      ],
      "state": 2
    },
    {
      "pos": [
        10,
        0,
        9
      ],
      "state": 2
    },
    {
      "pos": [
        10,
        0,
        10
      ],
      "state": 1
    },
    {
      "pos": [
        10,
        0,
        11
      ],
      "state": 1
    },
    {
      "pos": [
        10,
        0,
        12
      ],
      "state": 3
    },
    {
      "pos": [
        11,
        0,
        0
      ],
      "state": 0
    },
    {
      "pos": [
        11,
        0,
        1
      ],
      "state": 1
    },
    {
      "pos": [
        11,
        0,
        2
      ],
      "state": 1
    },
    {
      "pos": [
        11,
        0,
        3
      ],
      "state": 1
    },
    {
      "pos": [
        11,
        0,
        4
      ],
      "state": 1
    },
    {
      "pos": [
        11,
        0,
        5
      ],
      "state": 1
    },
    {
      "pos": [
        11,
        0,
        6
      ],
      "state": 1
    },
    {
      "pos": [
        11,
        0,
        7
      ],
      "state": 1
    },
    {
      "pos": [
        11,
        0,
        8
      ],
      "state": 1
    },
    {
      "pos": [
        11,
        0,
        9
      ],
      "state": 1
    },
    {
      "pos": [
        11,
        0,
        10
      ],
      "state": 1
    },
    {
      "pos": [
        11,
        0,
        11
      ],
      "state": 0
    },
    {
      "pos": [
        11,
        0,
        12
      ],
      "state": 1
    },
    {
      "pos": [
        12,
        0,
        0
      ],
      "state": 1
    },
    {
      "pos": [
        12,
        0,
        1
      ],
      "state": 1
    },
    {
      "pos": [
        12,
        0,
        2
      ],
      "state": 1
    },
    {
      "pos": [
        12,
        0,
        3
      ],
      "state": 1
    },
    {
      "pos": [
        12,
        0,
        4
      ],
      "state": 1
    },
    {
      "pos": [
        12,
        0,
        5
      ],
      "state": 1
    },
    {
      "pos": [
        12,
        0,
        6
      ],
      "state": 0
    },
    {
      "pos": [
        12,
        0,
        7
      ],
      "state": 1
    },
    {
      "pos": [
        12,
        0,
        8
      ],
      "state": 1
    },
    {
      "pos": [
        12,
        0,
        9
      ],
      "state": 1
    },
    {
      "pos": [
        12,
        0,
        10
      ],
      "state": 1
    },
    {
      "pos": [
        12,
        0,
        11
      ],
      "state": 1
    },
    {
      "pos": [
        12,
        0,
        12
      ],
      "state": 1
    },
    {
      "pos": [
        2,
        1,
        1
      ],
      "state": 5
    },
    {
      "pos": [
        2,
        1,
        2
      ],
      "state": 2
    },
    {
      "pos": [
        2,
        1,
        3
      ],
      "state": 2
    },
    {
      "pos": [
        2,
        1,
        4
      ],
      "state": 2
    },
    {
      "pos": [
        2,
        1,
        5
      ],
      "state": 2
    },
    {
      "pos": [
        2,
        1,
        6
      ],
      "state": 2
    },
    {
      "pos": [
        2,
        1,
        7
      ],
      "state": 2
    },
    {
      "pos": [
        2,
        1,
        8
      ],
      "state": 2
    },
    {
      "pos": [
        2,
        1,
        9
      ],
      "state": 5
    },
    {
      "pos": [
        2,
        1,
        11
      ],
      "state": 6
    },
    {
      "pos": [
        2,
        1,
        12
      ],
      "state": 7
    },
    {
      "pos": [
        3,
        1,
        1
      ],
      "state": 2
    },
    {
      "pos": [
        3,
        1,
        3
      ],
      "state": 8
    },
    {
      "pos": [
        3,
        1,
        4
      ],
      "state": 9
    },
    {
      "pos": [
        3,
        1,
        6
      ],
      "state": 8
    },
    {
      "pos": [
        3,
        1,
        7
      ],
      "state": 9
    },
    {
      "pos": [
        3,
        1,
        9
      ],
      "state": 2
    },
    {
      "pos": [
        3,
        1,
        11
      ],
      "state": 6
    },
    {
      "pos": [
        3,
        1,
        12
      ],
      "state": 10
    },
    {
      "pos": [
        4,
        1,
        1
      ],
      "state": 2
    },
    {
      "pos": [
        4,
        1,
        3
      ],
      "state": 8
    },
    {
      "pos": [
        4,
        1,
        4
      ],
      "state": 9
    },
    {
      "pos": [
        4,
        1,
        9
      ],
      "state": 2
    },
    {
      "pos": [
        4,
        1,
        11
      ],
      "state": 11
    },
    {
      "pos": [
        5,
        1,
        1
      ],
      "state": 2
    },
    {
      "pos": [
        5,
        1,
        9
      ],
      "state": 2
    },
    {
      "pos": [
        6,
        1,
        1
      ],
      "state": 2
    },
    {
      "pos": [
        6,
        1,
        9
      ],
      "state": 12
    },
    {
      "pos": [
        7,
        1,
        1
      ],
      "state": 2
    },
    {
      "pos": [
        7,
        1,
        9
      ],
      "state": 2
    },
    {
      "pos": [
        8,
        1,
        1
      ],
      "state": 2
    },
    {
      "pos": [
        8,
        1,
        3
      ],
      "state": 8
    },
    {
      "pos": [
        8,
        1,
        4
      ],
      "state": 9
    },
    {
      "pos": [
        8,
        1,
        9
      ],
      "state": 2
    },
    {
      "pos": [
        8,
        1,
        11
      ],
      "state": 11
    },
    {
      "pos": [
        9,
        1,
        1
      ],
      "state": 2
    },
    {
      "pos": [
        9,
        1,
        3
      ],
      "state": 8
    },
    {
      "pos": [
        9,
        1,
        4
      ],
      "state": 9
    },
    {
      "pos": [
        9,
        1,
        9
      ],
      "state": 2
    },
    {
      "pos": [
        9,
        1,
        11
      ],
      "state": 6
    },
    {
      "pos": [
        9,
        1,
        12
      ],
      "state": 10
    },
    {
      "pos": [
        10,
        1,
        1
      ],
      "state": 5
    },
    {
      "pos": [
        10,
        1,
        2
      ],
      "state": 2
    },
    {
      "pos": [
        10,
        1,
        3
      ],
      "state": 2
    },
    {
      "pos": [
        10,
        1,
        4
      ],
      "state": 2
    },
    {
      "pos": [
        10,
        1,
        5
      ],
      "state": 2
    },
    {
      "pos": [
        10,
        1,
        6
      ],
      "state": 2
    },
    {
      "pos": [
        10,
        1,
        7
      ],
      "state": 2
    },
    {
      "pos": [
        10,
        1,
        8
      ],
      "state": 2
    },
    {
      "pos": [
        10,
        1,
        9
      ],
      "state": 5
    },
    {
      "pos": [
        10,
        1,
        11
      ],
      "state": 6
    },
    {
      "pos": [
        10,
        1,
        12
      ],
      "state": 7
    },
    {
      "pos": [
        2,
        2,
        1
      ],
      "state": 5
    },
    {
      "pos": [
        2,
        2,
        2
      ],
      "state": 2
    },
    {
      "pos": [
        2,
        2,
        3
      ],
      "state": 13
    },
    {
      "pos": [
        2,
        2,
        4
      ],
      "state": 13
    },
    {
      "pos": [
        2,
        2,
        5
      ],
      "state": 2
    },
    {
      "pos": [
        2,
        2,
        6
      ],
      "state": 13
    },
    {
      "pos": [
        2,
        2,
        7
      ],
      "state": 13
    },
    {
      "pos": [
        2,
        2,
        8
      ],
      "state": 2
    },
    {
      "pos": [
        2,
        2,
        9
      ],
      "state": 5
    },
    {
      "pos": [
        3,
        2,
        1
      ],
      "state": 2
    },
    {
      "pos": [
        3,
        2,
        9
      ],
      "state": 13
    },
    {
      "pos": [
        4,
        2,
        1
      ],
      "state": 13
    },
    {
      "pos": [
        4,
        2,
        9
      ],
      "state": 13
    },
    {
      "pos": [
        4,
        2,
        11
      ],
      "state": 11
    },
    {
      "pos": [
        5,
        2,
        1
      ],
      "state": 13
    },
    {
      "pos": [
        5,
        2,
        9
      ],
      "state": 2
    },
    {
      "pos": [
        6,
        2,
        1
      ],
      "state": 13
    },
    {
      "pos": [
        6,
        2,
        9
      ],
      "state": 14
    },
    {
      "pos": [
        7,
        2,
        1
      ],
      "state": 13
    },
    {
      "pos": [
        7,
        2,
        9
      ],
      "state": 2
    },
    {
      "pos": [
        8,
        2,
        1
      ],
      "state": 13
    },
    {
      "pos": [
        8,
        2,
        9
      ],
      "state": 13
    },
    {
      "pos": [
        8,
        2,
        11
      ],
      "state": 11
    },
    {
      "pos": [
        9,
        2,
        1
      ],
      "state": 2
    },
    {
      "pos": [
        9,
        2,
        9
      ],
      "state": 13
    },
    {
      "pos": [
        10,
        2,
        1
      ],
      "state": 5
    },
    {
      "pos": [
        10,
        2,
        2
      ],
      "state": 2
    },
    {
      "pos": [
        10,
        2,
        3
      ],
      "state": 13
    },
    {
      "pos": [
        10,
        2,
        4
      ],
      "state": 13
    },
    {
      "pos": [
        10,
        2,
        5
      ],
      "state": 2
    },
    {
      "pos": [
        10,
        2,
        6
      ],
      "state": 13
    },
    {
      "pos": [
        10,
        2,
        7
      ],
      "state": 13
    },
    {
      "pos": [
        10,
        2,
        8
      ],
      "state": 2
    },
    {
      "pos": [
        10,
        2,
        9
      ],
      "state": 5
    },
    {
      "pos": [
        2,
        3,
        1
      ],
      "state": 5
    },
    {
      "pos": [
        2,
        3,
        2
      ],
      "state": 2
    },
    {
      "pos": [
        2,
        3,
        3
      ],
      "state": 13
    },
    {
      "pos": [
        2,
        3,
        4
      ],
      "state": 13
    },
    {
      "pos": [
        2,
        3,
        5
      ],
      "state": 2
    },
    {
      "pos": [
        2,
        3,
        6
      ],
      "state": 13
    },
    {
      "pos": [
        2,
        3,
        7
      ],
      "state": 13
    },
    {
      "pos": [
        2,
        3,
        8
      ],
      "state": 2
    },
    {
      "pos": [
        2,
        3,
        9
      ],
      "state": 5
    },
    {
      "pos": [
        3,
        3,
        1
      ],
      "state": 2
    },
    {
      "pos": [
        3,
        3,
        9
      ],
      "state": 13
    },
    {
      "pos": [
        4,
        3,
        1
      ],
      "state": 13
    },
    {
      "pos": [
        4,
        3,
        9
      ],
      "state": 13
    },
    {
      "pos": [
        4,
        3,
        11
      ],
      "state": 15
    },
    {
      "pos": [
        5,
        3,
        1
      ],
      "state": 13
    },
    {
      "pos": [
        5,
        3,
        9
      ],
      "state": 2
    },
    {
      "pos": [
        6,
        3,
        1
      ],
      "state": 13
    },
    {
      "pos": [
        6,
        3,
        9
      ],
      "state": 2
    },
    {
      "pos": [
        7,
        3,
        1
      ],
      "state": 13
    },
    {
      "pos": [
        7,
        3,
        9
      ],
      "state": 2
    },
    {
      "pos": [
        8,
        3,
        1
      ],
      "state": 13
    },
    {
      "pos": [
        8,
        3,
        9
      ],
      "state": 13
    },
    {
      "pos": [
        8,
        3,
        11
      ],
      "state": 15
    },
    {
      "pos": [
        9,
        3,
        1
      ],
      "state": 2
    },
    {
      "pos": [
        9,
        3,
        9
      ],
      "state": 13
    },
    {
      "pos": [
        10,
        3,
        1
      ],
      "state": 5
    },
    {
      "pos": [
        10,
        3,
        2
      ],
      "state": 2
    },
    {
      "pos": [
        10,
        3,
        3
      ],
      "state": 13
    },
    {
      "pos": [
        10,
        3,
        4
      ],
      "state": 13
    },
    {
      "pos": [
        10,
        3,
        5
      ],
      "state": 2
    },
    {
      "pos": [
        10,
        3,
        6
      ],
      "state": 13
    },
    {
      "pos": [
        10,
        3,
        7
      ],
      "state": 13
    },
    {
      "pos": [
        10,
        3,
        8
      ],
      "state": 2
    },
    {
      "pos": [
        10,
        3,
        9
      ],
      "state": 5
    },
    {
      "pos": [
        2,
        4,
        1
      ],
      "state": 5
    },
    {
      "pos": [
        2,
        4,
        2
      ],
      "state": 16
    },
    {
      "pos": [
        2,
        4,
        3
      ],
      "state": 16
    },
    {
      "pos": [
        2,
        4,
        4
      ],
      "state": 16
    },
    {
      "pos": [
        2,
        4,
        5
      ],
      "state": 16
    },
    {
      "pos": [
        2,
        4,
        6
      ],
      "state": 16
    },
    {
      "pos": [
        2,
        4,
        7
      ],
      "state": 16
    },
    {
      "pos": [
        2,
        4,
        8
      ],
      "state": 16
    },
    {
      "pos": [
        2,
        4,
        9
      ],
      "state": 5
    },
    {
      "pos": [
        3,
        4,
        1
      ],
      "state": 17
    },
    {
      "pos": [
        3,
        4,
        9
      ],
      "state": 17
    },
    {
      "pos": [
        4,
        4,
        1
      ],
      "state": 17
    },
    {
      "pos": [
        4,
        4,
        9
      ],
      "state": 17
    },
    {
      "pos": [
        5,
        4,
        1
      ],
      "state": 17
    },
    {
      "pos": [
        5,
        4,
        9
      ],
      "state": 17
    },
    {
      "pos": [
        6,
        4,
        1
      ],
      "state": 17
    },
    {
      "pos": [
        6,
        4,
        5
      ],
      "state": 18
    },
    {
      "pos": [
        6,
        4,
        9
      ],
      "state": 17
    },
    {
      "pos": [
        7,
        4,
        1
      ],
      "state": 17
    },
    {
      "pos": [
        7,
        4,
        9
      ],
      "state": 17
    },
    {
      "pos": [
        8,
        4,
        1
      ],
      "state": 17
    },
    {
      "pos": [
        8,
        4,
        9
      ],
      "state": 17
    },
    {
      "pos": [
        9,
        4,
        1
      ],
      "state": 17
    },
    {
      "pos": [
        9,
        4,
        9
      ],
      "state": 17
    },
    {
      "pos": [
        10,
        4,
        1
      ],
      "state": 5
    },
    {
      "pos": [
        10,
        4,
        2
      ],
      "state": 16
    },
    {
      "pos": [
        10,
        4,
        3
      ],
      "state": 16
    },
    {
      "pos": [
        10,
        4,
        4
      ],
      "state": 16
    },
    {
      "pos": [
        10,
        4,
        5
      ],
      "state": 16
    },
    {
      "pos": [
        10,
        4,
        6
      ],
      "state": 16
    },
    {
      "pos": [
        10,
        4,
        7
      ],
      "state": 16
    },
    {
      "pos": [
        10,
        4,
        8
      ],
      "state": 16
    },
    {
      "pos": [
        10,
        4,
        9
      ],
      "state": 5
    },
    {
      "pos": [
        1,
        5,
        0
      ],
      "state": 19
    },
    {
      "pos": [
        1,
        5,
        1
      ],
      "state": 19
    },
    {
      "pos": [
        1,
        5,
        2
      ],
      "state": 19
    },
    {
      "pos": [
        1,
        5,
        3
      ],
      "state": 19
    },
    {
      "pos": [
        1,
        5,
        4
      ],
      "state": 19
    },
    {
      "pos": [
        1,
        5,
        5
      ],
      "state": 19
    },
    {
      "pos": [
        1,
        5,
        6
      ],
      "state": 19
    },
    {
      "pos": [
        1,
        5,
        7
      ],
      "state": 19
    },
    {
      "pos": [
        1,
        5,
        8
      ],
      "state": 19
    },
    {
      "pos": [
        1,
        5,
        9
      ],
      "state": 19
    },
    {
      "pos": [
        1,
        5,
        10
      ],
      "state": 19
    },
    {
      "pos": [
        2,
        5,
        0
      ],
      "state": 20
    },
    {
      "pos": [
        2,
        5,
        1
      ],
      "state": 21
    },
    {
      "pos": [
        2,
        5,
        2
      ],
      "state": 20
    },
    {
      "pos": [
        2,
        5,
        3
      ],
      "state": 20
    },
    {
      "pos": [
        2,
        5,
        4
      ],
      "state": 20
    },
    {
      "pos": [
        2,
        5,
        5
      ],
      "state": 20
    },
    {
      "pos": [
        2,
        5,
        6
      ],
      "state": 20
    },
    {
      "pos": [
        2,
        5,
        7
      ],
      "state": 20
    },
    {
      "pos": [
        2,
        5,
        8
      ],
      "state": 20
    },
    {
      "pos": [
        2,
        5,
        9
      ],
      "state": 21
    },
    {
      "pos": [
        2,
        5,
        10
      ],
      "state": 20
    },
    {
      "pos": [
        3,
        5,
        1
      ],
      "state": 2
    },
    {
      "pos": [
        3,
        5,
        5
      ],
      "state": 17
    },
    {
      "pos": [
        3,
        5,
        9
      ],
      "state": 2
    },
    {
      "pos": [
        4,
        5,
        1
      ],
      "state": 2
    },
    {
      "pos": [
        4,
        5,
        5
      ],
      "state": 17
    },
    {
      "pos": [
        4,
        5,
        9
      ],
      "state": 2
    },
    {
      "pos": [
        5,
        5,
        1
      ],
      "state": 2
    },
    {
      "pos": [
        5,
        5,
        5
      ],
      "state": 17
    },
    {
      "pos": [
        5,
        5,
        9
      ],
      "state": 2
    },
    {
      "pos": [
        6,
        5,
        1
      ],
      "state": 13
    },
    {
      "pos": [
        6,
        5,
        5
      ],
      "state": 17
    },
    {
      "pos": [
        6,
        5,
        9
      ],
      "state": 13
    },
    {
      "pos": [
        7,
        5,
        1
      ],
      "state": 2
    },
    {
      "pos": [
        7,
        5,
        5
      ],
      "state": 17
    },
    {
      "pos": [
        7,
        5,
        9
      ],
      "state": 2
    },
    {
      "pos": [
        8,
        5,
        1
      ],
      "state": 2
    },
    {
      "pos": [
        8,
        5,
        5
      ],
      "state": 17
    },
    {
      "pos": [
        8,
        5,
        9
      ],
      "state": 2
    },
    {
      "pos": [
        9,
        5,
        1
      ],
      "state": 2
    },
    {
      "pos": [
        9,
        5,
        5
      ],
      "state": 17
    },
    {
      "pos": [
        9,
        5,
        9
      ],
      "state": 2
    },
    {
      "pos": [
        10,
        5,
        0
      ],
      "state": 20
    },
    {
      "pos": [
        10,
        5,
        1
      ],
      "state": 21
    },
    {
      "pos": [
        10,
        5,
        2
      ],
      "state": 20
    },
    {
      "pos": [
        10,
        5,
        3
      ],
      "state": 20
    },
    {
      "pos": [
        10,
        5,
        4
      ],
      "state": 20
    },
    {
      "pos": [
        10,
        5,
        5
      ],
      "state": 20
    },
    {
      "pos": [
        10,
        5,
        6
      ],
      "state": 20
    },
    {
      "pos": [
        10,
        5,
        7
      ],
      "state": 20
    },
    {
      "pos": [
        10,
        5,
        8
      ],
      "state": 20
    },
    {
      "pos": [
        10,
        5,
        9
      ],
      "state": 21
    },
    {
      "pos": [
        10,
        5,
        10
      ],
      "state": 20
    },
    {
      "pos": [
        11,
        5,
        0
      ],
      "state": 19
    },
    {
      "pos": [
        11,
        5,
        1
      ],
      "state": 19
    },
    {
      "pos": [
        11,
        5,
        2
      ],
      "state": 19
    },
    {
      "pos": [
        11,
        5,
        3
      ],
      "state": 19
    },
    {
      "pos": [
        11,
        5,
        4
      ],
      "state": 19
    },
    {
      "pos": [
        11,
        5,
        5
      ],
      "state": 19
    },
    {
      "pos": [
        11,
        5,
        6
      ],
      "state": 19
    },
    {
      "pos": [
        11,
        5,
        7
      ],
      "state": 19
    },
    {
      "pos": [
        11,
        5,
        8
      ],
      "state": 19
    },
    {
      "pos": [
        11,
        5,
        9
      ],
      "state": 19
    },
    {
      "pos": [
        11,
        5,
        10
      ],
      "state": 19
    },
    {
      "pos": [
        3,
        6,
        0
      ],
      "state": 19
    },
    {
      "pos": [
        3,
        6,
        1
      ],
      "state": 19
    },
    {
      "pos": [
        3,
        6,
        2
      ],
      "state": 19
    },
    {
      "pos": [
        3,
        6,
        3
      ],
      "state": 19
    },
    {
      "pos": [
        3,
        6,
        4
      ],
      "state": 19
    },
    {
      "pos": [
        3,
        6,
        5
      ],
      "state": 19
    },
    {
      "pos": [
        3,
        6,
        6
      ],
      "state": 19
    },
    {
      "pos": [
        3,
        6,
        7
      ],
      "state": 19
    },
    {
      "pos": [
        3,
        6,
        8
      ],
      "state": 19
    },
    {
      "pos": [
        3,
        6,
        9
      ],
      "state": 19
    },
    {
      "pos": [
        3,
        6,
        10
      ],
      "state": 19
    },
    {
      "pos": [
        4,
        6,
        0
      ],
      "state": 20
    },
    {
      "pos": [
        4,
        6,
        1
      ],
      "state": 21
    },
    {
      "pos": [
        4,
        6,
        2
      ],
      "state": 20
    },
    {
      "pos": [
        4,
        6,
        3
      ],
      "state": 20
    },
    {
      "pos": [
        4,
        6,
        4
      ],
      "state": 20
    },
    {
      "pos": [
        4,
        6,
        5
      ],
      "state": 20
    },
    {
      "pos": [
        4,
        6,
        6
      ],
      "state": 20
    },
    {
      "pos": [
        4,
        6,
        7
      ],
      "state": 20
    },
    {
      "pos": [
        4,
        6,
        8
      ],
      "state": 20
    },
    {
      "pos": [
        4,
        6,
        9
      ],
      "state": 21
    },
    {
      "pos": [
        4,
        6,
        10
      ],
      "state": 20
    },
    {
      "pos": [
        5,
        6,
        1
      ],
      "state": 2
    },
    {
      "pos": [
        5,
        6,
        9
      ],
      "state": 2
    },
    {
      "pos": [
        6,
        6,
        1
      ],
      "state": 2
    },
    {
      "pos": [
        6,
        6,
        9
      ],
      "state": 2
    },
    {
      "pos": [
        7,
        6,
        1
      ],
      "state": 2
    },
    {
      "pos": [
        7,
        6,
        9
      ],
      "state": 2
    },
    {
      "pos": [
        8,
        6,
        0
      ],
      "state": 20
    },
    {
      "pos": [
        8,
        6,
        1
      ],
      "state": 21
    },
    {
      "pos": [
        8,
        6,
        2
      ],
      "state": 20
    },
    {
      "pos": [
        8,
        6,
        3
      ],
      "state": 20
    },
    {
      "pos": [
        8,
        6,
        4
      ],
      "state": 20
    },
    {
      "pos": [
        8,
        6,
        5
      ],
      "state": 20
    },
    {
      "pos": [
        8,
        6,
        6
      ],
      "state": 20
    },
    {
      "pos": [
        8,
        6,
        7
      ],
      "state": 20
    },
    {
      "pos": [
        8,
        6,
        8
      ],
      "state": 20
    },
    {
      "pos": [
        8,
        6,
        9
      ],
      "state": 21
    },
    {
      "pos": [
        8,
        6,
        10
      ],
      "state": 20
    },
    {
      "pos": [
        9,
        6,
        0
      ],
      "state": 19
    },
    {
      "pos": [
        9,
        6,
        1
      ],
      "state": 19
    },
    {
      "pos": [
        9,
        6,
        2
      ],
      "state": 19
    },
    {
      "pos": [
        9,
        6,
        3
      ],
      "state": 19
    },
    {
      "pos": [
        9,
        6,
        4
      ],
      "state": 19
    },
    {
      "pos": [
        9,
        6,
        5
      ],
      "state": 19
    },
    {
      "pos": [
        9,
        6,
        6
      ],
      "state": 19
    },
    {
      "pos": [
        9,
        6,
        7
      ],
      "state": 19
    },
    {
      "pos": [
        9,
        6,
        8
      ],
      "state": 19
    },
    {
      "pos": [
        9,
        6,
        9
      ],
      "state": 19
    },
    {
      "pos": [
        9,
        6,
        10
      ],
      "state": 19
    },
    {
      "pos": [
        5,
        7,
        0
      ],
      "state": 19
    },
    {
      "pos": [
        5,
        7,
        1
      ],
      "state": 19
    },
    {
      "pos": [
        5,
        7,
        2
      ],
      "state": 19
    },
    {
      "pos": [
        5,
        7,
        3
      ],
      "state": 19
    },
    {
      "pos": [
        5,
        7,
        4
      ],
      "state": 19
    },
    {
      "pos": [
        5,
        7,
        5
      ],
      "state": 19
    },
    {
      "pos": [
        5,
        7,
        6
      ],
      "state": 19
    },
    {
      "pos": [
        5,
        7,
        7
      ],
      "state": 19
    },
    {
      "pos": [
        5,
        7,
        8
      ],
      "state": 19
    },
    {
      "pos": [
        5,
        7,
        9
      ],
      "state": 19
    },
    {
      "pos": [
        5,
        7,
        10
      ],
      "state": 19
    },
    {
      "pos": [
        6,
        7,
        0
      ],
      "state": 20
    },
    {
      "pos": [
        6,
        7,
        1
      ],
      "state": 21
    },
    {
      "pos": [
        6,
        7,
        2
      ],
      "state": 20
    },
    {
      "pos": [
        6,
        7,
        3
      ],
      "state": 20
    },
    {
      "pos": [
        6,
        7,
        4
      ],
      "state": 20
    },
    {
      "pos": [
        6,
        7,
        5
      ],
      "state": 20
    },
    {
      "pos": [
        6,
        7,
        6
      ],
      "state": 20
    },
    {
      "pos": [
        6,
        7,
        7
      ],
      "state": 20
    },
    {
      "pos": [
        6,
        7,
        8
      ],
      "state": 20
    },
    {
      "pos": [
        6,
        7,
        9
      ],
      "state": 21
    },
    {
      "pos": [
        6,
        7,
        10
      ],
      "state": 20
    },
    {
      "pos": [
        7,
        7,
        0
      ],
      "state": 19
    },
    {
      "pos": [
        7,
        7,
        1
      ],
      "state": 19
    },
    {
      "pos": [
        7,
        7,
        2
      ],
      "state": 19
    },
    {
      "pos": [
        7,
        7,
        3
      ],
      "state": 19
    },
    {
      "pos": [
        7,
        7,
        4
      ],
      "state": 19
    },
    {
      "pos": [
        7,
        7,
        5
      ],
      "state": 19
    },
    {
      "pos": [
        7,
        7,
        6
      ],
      "state": 19
    },
    {
      "pos": [
        7,
        7,
        7
      ],
      "state": 19
    },
    {
      "pos": [
        7,
        7,
        8
      ],
      "state": 19
    },
    {
      "pos": [
        7,
        7,
        9
      ],
      "state": 19
    },
    {
      "pos": [
        7,
        7,
        10
      ],
      "state": 19
    }
  ],
  "entities": []
}
