{
  "DataVersion": 3955,
  "size": [
    13,
    5,
    13
  ],
  "palette": [
    {
      "Name": "minecraft:mossy_stone_bricks"
    },
    {
      "Name": "minecraft:stone_bricks"
    },
    {
      "Name": "minecraft:grass_block",
      "Properties": {
        "snowy": "false"
      }
    },
    {
      "Name": "minecraft:smooth_stone"
    },
    {
      "Name": "minecraft:poppy"
    },
    {
      "Name": "minecraft:stone_brick_slab",
      "Properties": {
        "type": "bottom",
        "waterlogged": "false"
      }
    },
    {
      "Name": "minecraft:spruce_fence",
      "Properties": {
        "east": "false",
        "north": "false",
        "south": "false",
        "waterlogged": "false",
        "west": "false"
      }
    },
    {
      "Name": "minecraft:dandelion"
    },
    {
      "Name": "minecraft:oak_slab",
      "Properties": {
        "type": "top",
        "waterlogged": "false"
      }
    },
    {
      "Name": "minecraft:spruce_stairs",
      "Properties": {
        "facing": "north",
        "half": "bottom",
        "shape": "straight",
        "waterlogged": "false"
      }
    },
    {
      "Name": "minecraft:spruce_planks"
    },
    {
      "Name": "minecraft:lantern",
      "Properties": {
        "hanging": "true",
        "waterlogged": "false"
      }
    },
    {
      "Name": "minecraft:spruce_slab",
      "Properties": {
        "type": "bottom",
        "waterlogged": "false"
      }
    },
    {
      "Name": "minecraft:oak_slab",
      "Properties": {
        "type": "bottom",
        "waterlogged": "false"
      }
    },
    {
      "Name": "minecraft:lantern",
      "Properties": {
        "hanging": "false",
        "waterlogged": "false"
      }
    }
  ],
  "blocks": [
    {
      "pos": [
        0,
        0,
        0
      ],
      "state": 0
    },
    {
      "pos": [
        0,
        0,
        1
      ],
      "state": 1
    },
    {
      "pos": [
        0,
        0,
        2
      ],
      "state": 1
    },
    {
      "pos": [
        0,
        0,
        3
      ],
      "state": 1
    },
    {
      "pos": [
        0,
        0,
        4
      ],
      "state": 1
    },
    {
      "pos": [
        0,
        0,
        5
      ],
      "state": 1
    },
    {
      "pos": [
        0,
        0,
        6
      ],
      "state": 1
    },
    {
      "pos": [
        0,
        0,
        7
      ],
      "state": 1
    },
    {
      "pos": [
        0,
        0,
        8
      ],
      "state": 1
    },
    {
      "pos": [
        0,
        0,
        9
      ],
      "state": 1
    },
    {
      "pos": [
        0,
        0,
        10
      ],
      "state": 1
    },
    {
      "pos": [
        0,
        0,
        11
      ],
      "state": 0
    },
    {
      "pos": [
        0,
        0,
        12
      ],
      "state": 1
    },
    {
      "pos": [
        1,
        0,
        0
      ],
      "state": 2
    },
    {
      "pos": [
        1,
        0,
        1
      ],
      "state": 1
    },
    {
      "pos": [
        1,
        0,
        2
      ],
      "state": 1
    },
    {
      "pos": [
        1,
        0,
        3
      ],
      "state": 1
    },
    {
      "pos": [
        1,
        0,
        4
      ],
      "state": 1
    },
    {
      "pos": [
        1,
        0,
        5
      ],
      "state": 1
    },
    {
      "pos": [
        1,
        0,
        6
      ],
      "state": 0
    },
    {
      "pos": [
        1,
        0,
        7
      ],
      "state": 1
    },
    {
      "pos": [
        1,
        0,
        8
      ],
      "state": 1
    },
    {
      "pos": [
        1,
        0,
        9
      ],
      "state": 1
    },
    {
      "pos": [
        1,
        0,
        10
      ],
      "state": 1
    },
    {
      "pos": [
        1,
        0,
        11
      ],
      "state": 1
    },
    {
      "pos": [
        1,
        0,
        12
      ],
      "state": 1
    },
    {
      "pos": [
        2,
        0,
        0
      ],
      "state": 2
    },
    {
      "pos": [
        2,
        0,
        1
      ],
      "state": 0
    },
    {
      "pos": [
        2,
        0,
        2
      ],
      "state": 1
    },
    {
      "pos": [
        2,
        0,
        3
      ],
      "state": 1
    },
    {
      "pos": [
        2,
        0,
        4
      ],
      "state": 1
    },
    {
      "pos": [
        2,
        0,
        5
      ],
      "state": 1
    },
    {
      "pos": [
        2,
        0,
        6
      ],
      "state": 1
    },
    {
      "pos": [
        2,
        0,
        7
      ],
      "state": 1
    },
    {
      "pos": [
        2,
        0,
        8
      ],
      "state": 1
    },
    {
      "pos": [
        2,
        0,
        9
      ],
      "state": 1
    },
    {
      "pos": [
        2,
        0,
        10
      ],
      "state": 1
    },
    {
      "pos": [
        2,
        0,
        11
      ],
      "state": 1
    },
    {
      "pos": [
        2,
        0,
        12
      ],
      "state": 0
    },
    {
      "pos": [
        3,
        0,
        0
      ],
      "state": 2
    },
    {
      "pos": [
        3,
        0,
        1
      ],
      "state": 1
    },
    {
      "pos": [
        3,
        0,
        2
      ],
      "state": 1
    },
    {
      "pos": [
        3,
        0,
        3
      ],
      "state": 1
    },
    {
      "pos": [
        3,
        0,
        4
      ],
      "state": 1
    },
    {
      "pos": [
        3,
        0,
        5
      ],
      "state": 1
    },
    {
      "pos": [
        3,
        0,
        6
      ],
      "state": 1
    },
    {
      "pos": [
        3,
        0,
        7
      ],
      "state": 0
    },
    {
      "pos": [
        3,
        0,
        8
      ],
      "state": 1
    },
    {
      "pos": [
        3,
        0,
        9
      ],
      "state": 1
    },
    {
      "pos": [
        3,
        0,
        10
      ],
      "state": 1
    },
    {
      "pos": [
        3,
        0,
        11
      ],
      "state": 1
    },
    {
      "pos": [
        3,
        0,
        12
      ],
      "state": 1
    },
    {
      "pos": [
        4,
        0,
        0
      ],
      "state": 1
    },
    {
      "pos": [
        4,
        0,
        1
      ],
      "state": 1
    },
    {
      "pos": [
        4,
        0,
        2
      ],
      "state": 0
    },
    {
      "pos": [
        4,
        0,
        3
      ],
      "state": 1
    },
    {
      "pos": [
        4,
        0,
        4
      ],
      "state": 1
    },
    {
      "pos": [
        4,
        0,
        5
      ],
      "state": 1
    },
    {
      "pos": [
        4,
        0,
        6
      ],
      "state": 1
    },
    {
      "pos": [
        4,
        0,
        7
      ],
      "state": 1
    },
    {
      "pos": [
        4,
        0,
        8
      ],
      "state": 1
    },
    {
      "pos": [
        4,
        0,
        9
      ],
      "state": 1
    },
    {
      "pos": [
        4,
        0,
        10
      ],
      "state": 1
    },
    {
      "pos": [
        4,
        0,
        11
      ],
      "state": 1
    },
    {
      "pos": [
        4,
        0,
        12
      ],
      "state": 1
    },
    {
      "pos": [
        5,
        0,
        0
      ],
      "state": 3
    },
    {
      "pos": [
        5,
        0,
        1
      ],
      "state": 3
    },
    {
      "pos": [
        5,
        0,
        2
      ],
      "state": 3
    },
    {
      "pos": [
        5,
        0,
        3
      ],
      "state": 3
    },
    {
      "pos": [
        5,
        0,
        4
      ],
      "state": 3
    },
    {
      "pos": [
        5,
        0,
        5
      ],
      "state": 3
    },
    {
      "pos": [
        5,
        0,
        6
      ],
      "state": 3
    },
    {
      "pos": [
        5,
        0,
        7
      ],
      "state": 3
    },
    {
      "pos": [
        5,
        0,
        8
      ],
      "state": 3
    },
    {
      "pos": [
        5,
        0,
        9
      ],
      "state": 3
    },
    {
      "pos": [
        5,
        0,
        10
      ],
      "state": 3
    },
    {
      "pos": [
        5,
        0,
        11
      ],
      "state": 3
    },
    {
      "pos": [
        5,
        0,
        12
      ],
      "state": 3
    },
    {
      "pos": [
        6,
        0,
        0
      ],
      "state": 1
    },
    {
      "pos": [
        6,
        0,
        1
      ],
      "state": 1
    },
    {
      "pos": [
        6,
        0,
        2
      ],
      "state": 1
    },
    {
      "pos": [
        6,
        0,
        3
      ],
      "state": 1
    },
    {
      "pos": [
        6,
        0,
        4
      ],
      "state": 1
    },
    {
      "pos": [
        6,
        0,
        5
      ],
      "state": 1
    },
    {
      "pos": [
        6,
        0,
        6
      ],
      "state": 1
    },
    {
      "pos": [
        6,
        0,
        7
      ],
      "state": 1
    },
    {
      "pos": [
        6,
        0,
        8
      ],
      "state": 1
    },
    {
      "pos": [
        6,
        0,
        9
      ],
      "state": 1
    },
    {
      "pos": [
        6,
        0,
        10
      ],
      "state": 1
    },
    {
      "pos": [
        6,
        0,
        11
      ],
      "state": 1
    },
    {
      "pos": [
        6,
        0,
        12
      ],
      "state": 1
    },
    {
      "pos": [
        7,
        0,
        0
      ],
      "state": 3
    },
    {
      "pos": [
        7,
        0,
        1
      ],
      "state": 3
    },
    {
      "pos": [
        7,
        0,
        2
      ],
      "state": 3
    },
    {
      "pos": [
        7,
        0,
        3
      ],
      "state": 3
    },
    {
      "pos": [
        7,
        0,
        4
      ],
      "state": 3
    },
    {
      "pos": [
        7,
        0,
        5
      ],
      "state": 3
    },
    {
      "pos": [
        7,
        0,
        6
      ],
      "state": 3
    },
    {
      "pos": [
        7,
        0,
        7
      ],
      "state": 3
    },
    {
      "pos": [
        7,
        0,
        8
      ],
      "state": 3
    },
    {
      "pos": [
        7,
        0,
        9
      ],
      "state": 3
    },
    {
      "pos": [
        7,
        0,
        10
      ],
      "state": 3
    },
    {
      "pos": [
        7,
        0,
        11
      ],
      "state": 3
    },
    {
      "pos": [
        7,
        0,
        12
      ],
      "state": 3
    },
    {
      "pos": [
        8,
        0,
        0
      ],
      "state": 1
    },
    {
      "pos": [
        8,
        0,
        1
      ],
      "state": 1
    },
    {
      "pos": [
        8,
        0,
        2
      ],
      "state": 1
    },
    {
      "pos": [
        8,
        0,
        3
      ],
      "state": 1
    },
    {
      "pos": [
        8,
        0,
        4
      ],
      "state": 0
    },
    {
      "pos": [
        8,
        0,
        5
      ],
      "state": 1
    },
    {
      "pos": [
        8,
        0,
        6
      ],
      "state": 1
    },
    {
      "pos": [
        8,
        0,
        7
      ],
      "state": 1
    },
    {
      "pos": [
        8,
        0,
        8
      ],
      "state": 1
    },
    {
      "pos": [
        8,
        0,
        9
      ],
      "state": 1
    },
    {
      "pos": [
        8,
        0,
        10
      ],
      "state": 1
    },
    {
      "pos": [
        8,
        0,
        11
      ],
      "state": 1
    },
    {
      "pos": [
        8,
        0,
        12
      ],
      "state": 1
    },
    {
      "pos": [
        9,
        0,
        0
      ],
      "state": 2
    },
    {
      "pos": [
        9,
        0,
        1
      ],
      "state": 1
    },
    {
      "pos": [
        9,
        0,
        2
      ],
      "state": 1
    },
    {
      "pos": [
        9,
        0,
        3
      ],
      "state": 1
    },
    {
      "pos": [
        9,
        0,
        4
      ],
      "state": 1
    },
    {
      "pos": [
        9,
        0,
        5
      ],
      "state": 1
    },
    {
      "pos": [
        9,
        0,
        6
      ],
      "state": 1
    },
    {
      "pos": [
        9,
        0,
        7
      ],
      "state": 1
    },
    {
      "pos": [
        9,
        0,
        8
      ],
      "state": 1
    },
    {
      "pos": [
        9,
        0,
        9
      ],
      "state": 1
    },
    {
      "pos": [
        9,
        0,
        10
      ],
      "state": 0
    },
    {
      "pos": [
        9,
        0,
        11
      ],
      "state": 1
    },
    {
      "pos": [
        9,
        0,
        12
      ],
      "state": 1
    },
    {
      "pos": [
        10,
        0,
        0
      ],
      "state": 2
    },
    {
      "pos": [
        10,
        0,
        1
      ],
      "state": 1
    },
    {
      "pos": [
        10,
        0,
        2
      ],
      "state": 1
    },
    {
      "pos": [
        10,
        0,
        3
      ],
      "state": 1
    },
    {
      "pos": [
        10,
        0,
        4
      ],
      "state": 1
    },
    {
      "pos": [
        10,
        0,
        5
      ],
      "state": 0
    },
    {
      "pos": [
        10,
        0,
        6
      ],
      "state": 1
    },
    {
      "pos": [
        10,
        0,
        7
      ],
      "state": 1
    },
    {
      "pos": [
        10,
        0,
        8
      ],
      "state": 1
    },
    {
      "pos": [
        10,
        0,
        9
      ],
      "state": 1
    },
    {
      "pos": [
        10,
        0,
        10
      ],
      "state": 1
    },
    {
      "pos": [
        10,
        0,
        11
      ],
      "state": 1
    },
    {
      "pos": [
        10,
        0,
        12
      ],
      "state": 1
    },
    {
      "pos": [
        11,
        0,
        0
      ],
      "state": 2
    },
    {
      "pos": [
        11,
        0,
        1
      ],
      "state": 1
    },
    {
      "pos": [
        11,
        0,
        2
      ],
      "state": 1
    },
    {
      "pos": [
        11,
        0,
        3
      ],
      "state": 1
    },
    {
      "pos": [
        11,
        0,
        4
      ],
      "state": 1
    },
    {
      "pos": [
        11,
        0,
        5
      ],
      "state": 1
    },
    {
      "pos": [
        11,
        0,
        6
      ],
      "state": 1
    },
    {
      "pos": [
        11,
        0,
        7
      ],
      "state": 1
    },
    {
      "pos": [
        11,
        0,
        8
      ],
      "state": 1
    },
    {
      "pos": [
        11,
        0,
        9
      ],
      "state": 1
    },
    {
      "pos": [
        11,
        0,
        10
      ],
      "state": 1
    },
    {
      "pos": [
        11,
        0,
        11
      ],
      "state": 0
    },
    {
      "pos": [
        11,
        0,
        12
      ],
      "state": 1
    },
    {
      "pos": [
        12,
        0,
        0
      ],
      "state": 1
    },
    {
      "pos": [
        12,
        0,
        1
      ],
      "state": 1
    },
    {
      "pos": [
        12,
        0,
        2
      ],
      "state": 1
    },
    {
      "pos": [
        12,
        0,
        3
      ],
      "state": 1
    },
    {
      "pos": [
        12,
        0,
        4
      ],
      "state": 1
    },
    {
      "pos": [
        12,
        0,
        5
      ],
      "state": 1
    },
    {
      "pos": [
        12,
        0,
        6
      ],
      "state": 0
    },
    {
      "pos": [
        12,
        0,
        7
      ],
      "state": 1
    },
    {
      "pos": [
        12,
        0,
        8
      ],
      "state": 1
    },
    {
      "pos": [
        12,
        0,
        9
      ],
      "state": 1
    },
    {
      "pos": [
        12,
        0,
        10
      ],
      "state": 1
    },
    {
      "pos": [
        12,
        0,
        11
      ],
      "state": 1
    },
    {
      "pos": [
        12,
        0,
        12
      ],
      "state": 1
    },
    {
      "pos": [
        1,
        1,
        0
      ],
      "state": 4
    },
    {
      "pos": [
        1,
        1,
        1
      ],
      "state": 5
    },
    {
      "pos": [
        1,
        1,
        3
      ],
      "state": 6
    },
    {
      "pos": [
        1,
        1,
        7
      ],
      "state": 6
    },
    {
      "pos": [
        1,
        1,
        11
      ],
      "state": 6
    },
    {
      "pos": [
        2,
        1,
        0
      ],
      "state": 7
    },
    {
      "pos": [
        2,
        1,
        1
      ],
      "state": 5
    },
    {
      "pos": [
        2,
        1,
        4
      ],
      "state": 8
    },
    {
      "pos": [
        2,
        1,
        5
      ],
      "state": 8
    },
    {
      "pos": [
        2,
        1,
        6
      ],
      "state": 8
    },
    {
      "pos": [
        2,
        1,
        10
      ],
      "state": 9
    },
    {
      "pos": [
        3,
        1,
        0
      ],
      "state": 4
    },
    {
      "pos": [
        3,
        1,
        1
      ],
      "state": 5
    },
    {
      "pos": [
        3,
        1,
        10
      ],
      "state": 9
    },
    {
      "pos": [
        4,
        1,
        3
      ],
      "state": 6
    },
    {
      "pos": [
        4,
        1,
        4
      ],
      "state": 10
    },
    {
      "pos": [
        4,
        1,
        5
      ],
      "state": 10
    },
    {
      "pos": [
        4,
        1,
        6
      ],
      "state": 10
    },
    {
      "pos": [
        4,
        1,
        7
      ],
      "state": 6
    },
    {
      "pos": [
        8,
        1,
        3
      ],
      "state": 6
    },
    {
      "pos": [
        8,
        1,
        4
      ],
      "state": 10
    },
    {
      "pos": [
        8,
        1,
        5
      ],
      "state": 10
    },
    {
      "pos": [
        8,
        1,
        6
      ],
      "state": 10
    },
    {
      "pos": [
        8,
        1,
        7
      ],
      "state": 6
    },
    {
      "pos": [
        9,
        1,
        0
      ],
      "state": 4
    },
    {
      "pos": [
        9,
        1,
        1
      ],
      "state": 5
    },
    {
      "pos": [
        9,
        1,
        10
      ],
      "state": 9
    },
    {
      "pos": [
        10,
        1,
        0
      ],
      "state": 7
    },
    {
      "pos": [
        10,
        1,
        1
      ],
      "state": 5
    },
    {
      "pos": [
        10,
        1,
        4
      ],
      "state": 8
    },
    {
      "pos": [
        10,
        1,
        5
      ],
      "state": 8
    },
    {
      "pos": [
        10,
        1,
        6
      ],
      "state": 8
    },
    {
      "pos": [
        10,
        1,
        10
      ],
      "state": 9
    },
    {
      "pos": [
        11,
        1,
        0
      ],
      "state": 4
    },
    {
      "pos": [
        11,
        1,
        1
      ],
      "state": 5
    },
    {
      "pos": [
        11,
        1,
        3
      ],
      "state": 6
    },
    {
      "pos": [
        11,
        1,
        7
      ],
      "state": 6
    },
    {
      "pos": [
        11,
        1,
        11
      ],
      "state": 6
    },
    {
      "pos": [
        1,
        2,
        3
      ],
      "state": 6
    },
    {
      "pos": [
        1,
        2,
        7
      ],
      "state": 6
    },
    {
      "pos": [
        1,
        2,
        11
      ],
      "state": 6
    },
    {
      "pos": [
        4,
        2,
        3
      ],
      "state": 6
    },
    {
      "pos": [
        4,
        2,
        7
      ],
      "state": 6
    },
    {
      "pos": [
        8,
        2,
        3
      ],
      "state": 6
    },
    {
      "pos": [
        8,
        2,
        7
      ],
      "state": 6
    },
    {
      "pos": [
        11,
        2,
        3
      ],
      "state": 6
    },
    {
      "pos": [
        11,
        2,
        7
      ],
      "state": 6
    },
    {
      "pos": [
        11,
        2,
        11
      ],
      "state": 6
    },
    {
      "pos": [
        1,
        3,
        3
      ],
      "state": 6
    },
    {
      "pos": [
        1,
        3,
        7
      ],
      "state": 6
    },
    {
      "pos": [
        1,
        3,
        11
      ],
      "state": 6
    },
    {
      "pos": [
        2,
        3,
        3
      ],
      "state": 11
    },
    {
      "pos": [
        2,
        3,
        7
      ],
      "state": 11
    },
    {
      "pos": [
        4,
        3,
        3
      ],
      "state": 6
    },
    {
      "pos": [
        4,
        3,
        7
      ],
      "state": 6
    },
    {
      "pos": [
        8,
        3,
        3
      ],
      "state": 6
    },
    {
      "pos": [
        8,
        3,
        7
      ],
      "state": 6
    },
    {
      "pos": [
        10,
        3,
        3
      ],
      "state": 11
    },
    {
      "pos": [
        10,
        3,
        7
      ],
      "state": 11
    },
    {
      "pos": [
        11,
        3,
        3
      ],
      "state": 6
    },
    {
      "pos": [
        11,
        3,
        7
      ],
      "state": 6
    },
    {
      "pos": [
        11,
        3,
        11
      ],
      "state": 6
    },
    {
      "pos": [
        0,
        4,
        2
      ],
      "state": 12
    },
    {
      "pos": [
        0,
        4,
        3
      ],
      "state": 13
    },
    {
      "pos": [
        0,
        4,
        4
      ],
      "state": 12
    },
    {
      "pos": [
        0,
        4,
        5
      ],
      "state": 13
    },
    {
      "pos": [
        0,
        4,
        6
      ],
      "state": 12
    },
    {
      "pos": [
        0,
        4,
        7
      ],
      "state": 13
    },
    {
      "pos": [
        0,
        4,
        8
      ],
      "state": 12
    },
    {
      "pos": [
        1,
        4,
        2
      ],
      "state": 12
    },
    {
      "pos": [
        1,
        4,
        3
      ],
      "state": 13
    },
    {
      "pos": [
        1,
        4,
        4
      ],
      "state": 12
    },
    {
      "pos": [
        1,
        4,
        5
      ],
      "state": 13
    },
    {
      "pos": [
        1,
        4,
        6
      ],
      "state": 12
    },
    {
      "pos": [
        1,
        4,
        7
      ],
      "state": 13
    },
    {
      "pos": [
        1,
        4,
        8
      ],
      "state": 12
    },
    {
      "pos": [
        1,
        4,
        11
      ],
      "state": 14
    },
    {
      "pos": [
        2,
        4,
        2
      ],
      "state": 12
    },
    {
      "pos": [
        2,
        4,
        3
      ],
      "state": 13
    },
    {
      "pos": [
        2,
        4,
        4
      ],
      "state": 12
    },
    {
      "pos": [
        2,
        4,
        5
      ],
      "state": 13
    },
    {
      "pos": [
        2,
        4,
        6
      ],
      "state": 12
    },
    {
      "pos": [
        2,
        4,
        7
      ],
      "state": 13
    },
    {
      "pos": [
        2,
        4,
        8
      ],
      "state": 12
    },
    {
      "pos": [
        3,
        4,
        2
      ],
      "state": 12
    },
    {
      "pos": [
        3,
        4,
        3
      ],
      "state": 13
    },
    {
      "pos": [
        3,
        4,
        4
      ],
      "state": 12
    },
    {
      "pos": [
        3,
        4,
        5
      ],
      "state": 13
    },
    {
      "pos": [
        3,
        4,
        6
      ],
      "state": 12
    },
    {
      "pos": [
        3,
        4,
        7
      ],
      "state": 13
    },
    {
      "pos": [
        3,
        4,
        8
      ],
      "state": 12
    },
    {
      "pos": [
        4,
        4,
        2
      ],
      "state": 12
    },
    {
      "pos": [
        4,
        4,
        3
      ],
      "state": 13
    },
    {
      "pos": [
        4,
        4,
        4
      ],
      "state": 12
    },
    {
      "pos": [
        4,
        4,
        5
      ],
      "state": 13
    },
    {
      "pos": [
        4,
        4,
        6
      ],
      "state": 12
    },
    {
      "pos": [
        4,
        4,
        7
      ],
      "state": 13
    },
    {
      "pos": [
        4,
        4,
        8
      ],
      "state": 12
    },
    {
      "pos": [
        8,
        4,
        2
      ],
      "state": 12
    },
    {
      "pos": [
        8,
        4,
        3
      ],
      "state": 13
    },
    {
      "pos": [
        8,
        4,
        4
      ],
      "state": 12
    },
    {
      "pos": [
        8,
        4,
        5
      ],
      "state": 13
    },
    {
      "pos": [
        8,
        4,
        6
      ],
      "state": 12
    },
    {
      "pos": [
        8,
        4,
        7
      ],
      "state": 13
    },
    {
      "pos": [
        8,
        4,
        8
      ],
      "state": 12
    },
    {
      "pos": [
        9,
        4,
        2
      ],
      "state": 12
    },
    {
      "pos": [
        9,
        4,
        3
      ],
      "state": 13
    },
    {
      "pos": [
        9,
        4,
        4
      ],
      "state": 12
    },
    {
      "pos": [
        9,
        4,
        5
      ],
      "state": 13
    },
    {
      "pos": [
        9,
        4,
        6
      ],
      "state": 12
    },
    {
      "pos": [
        9,
        4,
        7
      ],
      "state": 13
    },
    {
      "pos": [
        9,
        4,
        8
      ],
      "state": 12
    },
    {
      "pos": [
        10,
        4,
        2
      ],
      "state": 12
    },
    {
      "pos": [
        10,
        4,
        3
      ],
      "state": 13
    },
    {
      "pos": [
        10,
        4,
        4
      ],
      "state": 12
    },
    {
      "pos": [
        10,
        4,
        5
      ],
      "state": 13
    },
    {
      "pos": [
        10,
        4,
        6
      ],
      "state": 12
    },
    {
      "pos": [
        10,
        4,
        7
      ],
      "state": 13
    },
    {
      "pos": [
        10,
        4,
        8
      ],
      "state": 12
    },
    {
      "pos": [
        11,
        4,
        2
      ],
      "state": 12
    },
    {
      "pos": [
        11,
        4,
        3
      ],
      "state": 13
    },
    {
      "pos": [
        11,
        4,
        4
      ],
      "state": 12
    },
    {
      "pos": [
        11,
        4,
        5
      ],
      "state": 13
    },
    {
      "pos": [
        11,
        4,
        6
      ],
      "state": 12
    },
    {
      "pos": [
        11,
        4,
        7
      ],
      "state": 13
    },
    {
      "pos": [
        11,
        4,
        8
      ],
      "state": 12
    },
    {
      "pos": [
        11,
        4,
        11
      ],
      "state": 14
    },
    {
      "pos": [
        12,
        4,
        2
      ],
      "state": 12
    },
    {
      "pos": [
        12,
        4,
        3
      ],
      "state": 13
    },
    {
      "pos": [
        12,
        4,
        4
      ],
      "state": 12
    },
    {
      "pos": [
        12,
        4,
        5
      ],
      "state": 13
    },
    {
      "pos": [
        12,
        4,
        6
      ],
      "state": 12
    },
    {
      "pos": [
        12,
        4,
        7
      ],
      "state": 13
    },
    {
      "pos": [
        12,
        4,
        8
      ],
      "state": 12
    }
  ],
  "entities": []
}
